Unable to init server: Could not connect: Connection refused
Unable to init server: Could not connect: Connection refused

(eval_runs.py:25241): Gdk-CRITICAL **: 20:58:30.216: gdk_cursor_new_for_display: assertion 'GDK_IS_DISPLAY (display)' failed
Now in directory  1571447
Incomplete experiment output in runs/mli_cifar10/1571447
Now in directory  1571495
Now in directory  _sources
Now in directory  1571415
Incomplete experiment output in runs/mli_cifar10/1571415
Now in directory  hi
Now in directory  1571672
Now in directory  1571543
Now in directory  1571670
Now in directory  1571669
Now in directory  1571677
Now in directory  hi_from_fileobserver
Now in directory  1571577
Found 9 runs
{'alpha_steps': 2, 'batchsize': 128, 'beta': 0.9, 'cuda': True, 'datasize': 60000, 'decay_factor': 0.1, 'decay_milestones': [60, 90, 120], 'dset_name': 'cifar10', 'epochs': 2, 'eval_gl': False, 'identity_init': True, 'init_type': 'default', 'log_wdist': True, 'loss_fn': 'ce', 'lr': 0.1, 'min_loss_epoch_check': 35, 'min_loss_threshold': 1.5, 'model_name': 'alexnet', 'num_classes': 10, 'optim_name': 'sgd', 'run_num': 1, 'save_freq': 25, 'seed': 17, 'tag': 'cifar10', 'weight_decay': 0.0001, 'run_id': '1571495'}
{'alpha_steps': 3, 'batchsize': 128, 'beta': 0.9, 'cuda': True, 'datasize': 60000, 'decay_factor': 0.1, 'decay_milestones': [60, 90, 120], 'dset_name': 'cifar10', 'epochs': 3, 'eval_gl': True, 'identity_init': True, 'init_type': 'default', 'log_wdist': True, 'loss_fn': 'ce', 'lr': 0.1, 'min_loss_epoch_check': 35, 'min_loss_threshold': 1.5, 'model_name': 'alexnet', 'num_classes': 10, 'optim_name': 'sgd', 'save_freq': 25, 'seed': 17, 'tag': 'cifar10', 'weight_decay': 0.0001, 'run_id': 'hi'}
Traceback (most recent call last):
  File "scripts/train_cifar/eval/eval_runs.py", line 119, in <module>
    process_experiments(args.expdir, args.outdir)
  File "scripts/train_cifar/eval/eval_runs.py", line 114, in process_experiments
    plot_interp(all_configs[i], all_metrics[i], outdir)
  File "/usr/xtmp/CSPlus/VOLDNN/Annie/mli-release/lib/mli_eval/plotting/interp.py", line 97, in plot_interp
    run_num = config["run_num"]
KeyError: 'run_num'
