INFO - mli_cifar10 - Running command 'main'
INFO - mli_cifar10 - Started run with ID "hi_from_fileobserver"
<sacred.run.Run object at 0x1457a72c5358>
<class 'sacred.run.Run'>
hi_from_fileobserver
Files already downloaded and verified
Files already downloaded and verified
No checkpoint found. Training from scratch.
ERROR - mli_cifar10 - Failed after 0:00:04!
Traceback (most recent calls WITHOUT Sacred internals):
  File "scripts/train_cifar/train.py", line 298, in main
    model, train_loader, optimizer, scheduler, cfg, _run
  File "scripts/train_cifar/train.py", line 194, in train_network
    }, init_outfile)
  File "/home/home4/aw364/.local/lib/python3.6/site-packages/torch/serialization.py", line 327, in save
    with _open_file_like(f, 'wb') as opened_file:
  File "/home/home4/aw364/.local/lib/python3.6/site-packages/torch/serialization.py", line 212, in _open_file_like
    return _open_file(name_or_buffer, mode)
  File "/home/home4/aw364/.local/lib/python3.6/site-packages/torch/serialization.py", line 193, in __init__
    super(_open_file, self).__init__(open(name, mode))
FileNotFoundError: [Errno 2] No such file or directory: 'runs/mli_cifar10/rundir/init.pt'

